Workbook

Sheet 작업 목록
A1: No | B1: 대목적 | C1: 중목적 | D1: 소목적 | E1: 상태 | F1: 비고 | G1: 대목적(집계용)
A2: 1 | B2: 1. 기획/설계 | C2: 핵심 시스템 기획 | D2: 컨셉·역할 구성(진짜/모방자/판정단) 확정 | E2: 완료 | F2: 기획서 §1-2 | G2: 1. 기획/설계
A3: 2 | D3: 8단계 라운드 구조 설계 | E3: 완료 | F3: 기획서 §6 | G3: 1. 기획/설계
A4: 3 | D4: 맵 6구역 설계 | E4: 완료 | F4: 기획서 §5 | G4: 1. 기획/설계
A5: 4 | D5: 위장 시스템(얼굴/음성) 설계 | E5: 완료 | F5: 기획서 §3 | G5: 1. 기획/설계
A6: 5 | D6: 이모트 4종 설계 | E6: 완료 | F6: 기획서 §4 | G6: 1. 기획/설계
A7: 6 | D7: 로비 사전 설정 옵션 설계 | E7: 완료 | F7: 기획서 §9 | G7: 1. 기획/설계
A8: 7 | D8: C++ 클래스/애셋/블루프린트 목록 설계 | E8: 완료 | F8: 기획서 §11~14 | G8: 1. 기획/설계
A9: 8 | C9: 커스터마이징 메커닉 기획 | D9: 로비 외형 커스터마이징 + 역할배정 시 스냅샷 복제 설계 | E9: 완료 | F9: 기획서 §3 최신 개정 | G9: 1. 기획/설계
A10: 9 | D10: 모방자 재조정(모창 준비) 시간·UI 세부 확정 | E10: 예정 | F10: 기획서 §17 | G10: 1. 기획/설계
A11: 10 | D11: 커스터마이징 파츠 범위·SD 로우폴리 애셋팩 확정 | E11: 예정 | F11: 기획서 §17 — 9/13 물범 캐릭터 채택으로 사람 베이스 계획은 사실상 보류, §6.5 참고 | G11: 1. 기획/설계
A12: 11 | D12: 판정단 더미 편집 화면 연출 확정 | E12: 예정 | F12: 기획서 §17 | G12: 1. 기획/설계
A13: 12 | C13: 미확정 항목 확정 | D13: 판정단 2인 모드 투표/면담 규칙 | E13: 예정 | F13: 기획서 §16, TODO.md §6 | G13: 1. 기획/설계
A14: 13 | D14: 진짜 지정 방식 — 후보자 투표 세부 흐름 | E14: 예정 | F14: 기획서 §16, TODO.md §6 | G14: 1. 기획/설계
A15: 14 | D15: 소음 소품 밸런스(반경/쿨다운/주목도) | E15: 예정 | F15: 기획서 §16, 플레이테스트로 결정 예정 | G15: 1. 기획/설계
A16: 15 | D16: 실제 구현된 신규 소품(Boombox/Basketball/BasketballHoop/StunGun)을 기획서에 반영할지 결정 | E16: 예정 | F16: 설계 8종 vs 실제 구현 6종 divergence — 여전히 미해결 | G16: 1. 기획/설계
A17: 16 | D17: 조작 탭의 사격/무기교체 키 재배정 UI 정리 여부 결정 | E17: 완료 | F17: 9/8 — Variant_Shooter 잔재(IA_Shoot/IA_SwapWeapon) 제거로 확정 | G17: 1. 기획/설계
A18: 17 | D18: 물범(스태틱 메시) 채택에 따른 커스터마이징/1인칭 구조 재설계 여부 결정 | E18: 예정 | F18: TODO.md §3 — (a)물범 애니메이션 나올 때까지 보류 (b)캡슐 고정 소켓으로 대체 (c)물범엔 커스터마이징 포기, 3안 중 사용자 결정 필요 | G18: 1. 기획/설계
A19: 18 | C19: 문서화(신규) | D19: docs/TODO.md 신설 — 실행 가능한 펀치리스트로 재정리, PROJECT_STATUS.md는 9/1 기준 stale로 표시 | E19: 완료 | F19: 9/15 — todo.txt(전체 세션 로그)와 역할 분리 | G19: 1. 기획/설계
A20: 19 | D20: todo.txt를 프로젝트 루트에서 docs/ 하위로 이동 | E20: 완료 | F20: 9/16 커밋 | G20: 1. 기획/설계
A21: 20 | B21: 2. 계정/행정 | C21: 스팀 | D21: Steamworks 파트너 계정 등록 | E21: 예정 | G21: 2. 계정/행정
A22: 21 | D22: 실제 게임 App ID 발급 | E22: 예정 | G22: 2. 계정/행정
A23: 22 | D23: Steam Direct 등록비($100) 납부 | E23: 예정 | G23: 2. 계정/행정
A24: 23 | D24: 스팀 스토어 페이지 개설 | E24: 예정 | G24: 2. 계정/행정
A25: 24 | C25: 국내 게임물 심의 | D25: 게임콘텐츠등급분류위원회(GCRB) 등급분류 신청 | E25: 예정 | G25: 2. 계정/행정
A26: 25 | D26: 개인/소규모 개발자 심의 수수료 50% 할인 신청 | E26: 예정 | G26: 2. 계정/행정
A27: 26 | C27: 음성 스택 계정 | D27: Epic Games Dev Portal 조직/Product/Client 생성 | E27: 예정 | F27: Week 6 음성 시스템의 유일한 외부 블로커 — TODO.md §7 | G27: 2. 계정/행정
A28: 27 | D28: EOS 자격증명(ProductId/SandboxId/DeploymentId/ClientId/ClientSecret)을 DefaultEngine.ini에 반영 | E28: 예정 | G28: 2. 계정/행정
A29: 28 | C29: 버전 관리 및 팀 | D29: Git 저장소 초기화 | E29: 완료 | G29: 2. 계정/행정
A30: 29 | D30: 원격 Git 호스트(GitHub 등) 연결 및 push | E30: 완료 | G30: 2. 계정/행정
A31: 30 | D31: 개발 규모 확정(1인 개발, 다기기 작업) | E31: 완료 | F31: PC2 등 여러 기기에서 작업, 9/13 머지 충돌 1회 발생·해결 | G31: 2. 계정/행정
A32: 31 | B32: 3. 네트워킹 & 세션 | C32: 스팀 세션 | D32: 세션 생성(Host Game) | E32: 완료 | G32: 3. 네트워킹 & 세션
A33: 32 | D33: 초대 전용 참가 흐름 | E33: 완료 | G33: 3. 네트워킹 & 세션
A34: 33 | D34: 방 목록 검색/브라우징 | E34: 완료 | F34: 설계상 의도적으로 미제공(초대 전용 파티게임) | G34: 3. 네트워킹 & 세션
A35: 34 | D35: 라이브 세션 설정 실시간 갱신 | E35: 완료 | G35: 3. 네트워킹 & 세션
A36: 35 | D36: 스팀 리치 프레즌스 | E36: 완료 | G36: 3. 네트워킹 & 세션
A37: 36 | D37: 세션 종료 후 로비 복귀 | E37: 완료 | G37: 3. 네트워킹 & 세션
A38: 37 | C38: P2P 네트워킹 | D38: SteamSockets NetDriver 연동 | E38: 완료 | G38: 3. 네트워킹 & 세션
A39: 38 | D39: P2P 릴레이 설정 | E39: 완료 | G39: 3. 네트워킹 & 세션
A40: 39 | D40: 실제 App ID 반영 후 재검증 | E40: 예정 | G40: 3. 네트워킹 & 세션
...

Sheet 요약
A1: 대목적 | B1: 완료 | C1: 부분완료 | D1: 예정 | E1: 합계 | F1: 진행률
A2: 1. 기획/설계 | B2: =COUNTIFS('작업 목록'!$G$2:$G$252,A2,'작업 목록'!$E$2:$E$252,"완료") -> 11 | C2: =COUNTIFS('작업 목록'!$G$2:$G$252,A2,'작업 목록'!$E$2:$E$252,"부분완료") -> 0 | D2: =COUNTIFS('작업 목록'!$G$2:$G$252,A2,'작업 목록'!$E$2:$E$252,"예정") -> 8 | E2: =SUM(B2:D2) -> 19 | F2: =IF(E2=0,0,(B2+C2*0.5)/E2) -> 0.57894737
A3: 2. 계정/행정 | B3: =COUNTIFS('작업 목록'!$G$2:$G$252,A3,'작업 목록'!$E$2:$E$252,"완료") -> 3 | C3: =COUNTIFS('작업 목록'!$G$2:$G$252,A3,'작업 목록'!$E$2:$E$252,"부분완료") -> 0 | D3: =COUNTIFS('작업 목록'!$G$2:$G$252,A3,'작업 목록'!$E$2:$E$252,"예정") -> 8 | E3: =SUM(B3:D3) -> 11 | F3: =IF(E3=0,0,(B3+C3*0.5)/E3) -> 0.27272727
A4: 3. 네트워킹 & 세션 | B4: =COUNTIFS('작업 목록'!$G$2:$G$252,A4,'작업 목록'!$E$2:$E$252,"완료") -> 10 | C4: =COUNTIFS('작업 목록'!$G$2:$G$252,A4,'작업 목록'!$E$2:$E$252,"부분완료") -> 0 | D4: =COUNTIFS('작업 목록'!$G$2:$G$252,A4,'작업 목록'!$E$2:$E$252,"예정") -> 1 | E4: =SUM(B4:D4) -> 11 | F4: =IF(E4=0,0,(B4+C4*0.5)/E4) -> 0.90909091
A5: 4. 로비 | B5: =COUNTIFS('작업 목록'!$G$2:$G$252,A5,'작업 목록'!$E$2:$E$252,"완료") -> 19 | C5: =COUNTIFS('작업 목록'!$G$2:$G$252,A5,'작업 목록'!$E$2:$E$252,"부분완료") -> 1 | D5: =COUNTIFS('작업 목록'!$G$2:$G$252,A5,'작업 목록'!$E$2:$E$252,"예정") -> 3 | E5: =SUM(B5:D5) -> 23 | F5: =IF(E5=0,0,(B5+C5*0.5)/E5) -> 0.84782609
A6: 5. 라운드 진행 로직 | B6: =COUNTIFS('작업 목록'!$G$2:$G$252,A6,'작업 목록'!$E$2:$E$252,"완료") -> 9 | C6: =COUNTIFS('작업 목록'!$G$2:$G$252,A6,'작업 목록'!$E$2:$E$252,"부분완료") -> 2 | D6: =COUNTIFS('작업 목록'!$G$2:$G$252,A6,'작업 목록'!$E$2:$E$252,"예정") -> 10 | E6: =SUM(B6:D6) -> 21 | F6: =IF(E6=0,0,(B6+C6*0.5)/E6) -> 0.47619048
A7: 6. 캐릭터 시스템 | B7: =COUNTIFS('작업 목록'!$G$2:$G$252,A7,'작업 목록'!$E$2:$E$252,"완료") -> 14 | C7: =COUNTIFS('작업 목록'!$G$2:$G$252,A7,'작업 목록'!$E$2:$E$252,"부분완료") -> 1 | D7: =COUNTIFS('작업 목록'!$G$2:$G$252,A7,'작업 목록'!$E$2:$E$252,"예정") -> 10 | E7: =SUM(B7:D7) -> 25 | F7: =IF(E7=0,0,(B7+C7*0.5)/E7) -> 0.58
A8: 7. 애니메이션 | B8: =COUNTIFS('작업 목록'!$G$2:$G$252,A8,'작업 목록'!$E$2:$E$252,"완료") -> 1 | C8: =COUNTIFS('작업 목록'!$G$2:$G$252,A8,'작업 목록'!$E$2:$E$252,"부분완료") -> 1 | D8: =COUNTIFS('작업 목록'!$G$2:$G$252,A8,'작업 목록'!$E$2:$E$252,"예정") -> 10 | E8: =SUM(B8:D8) -> 12 | F8: =IF(E8=0,0,(B8+C8*0.5)/E8) -> 0.125
A9: 8. 사운드 | B9: =COUNTIFS('작업 목록'!$G$2:$G$252,A9,'작업 목록'!$E$2:$E$252,"완료") -> 28 | C9: =COUNTIFS('작업 목록'!$G$2:$G$252,A9,'작업 목록'!$E$2:$E$252,"부분완료") -> 0 | D9: =COUNTIFS('작업 목록'!$G$2:$G$252,A9,'작업 목록'!$E$2:$E$252,"예정") -> 20 | E9: =SUM(B9:D9) -> 48 | F9: =IF(E9=0,0,(B9+C9*0.5)/E9) -> 0.58333333
A10: 9. UI/UX 화면 | B10: =COUNTIFS('작업 목록'!$G$2:$G$252,A10,'작업 목록'!$E$2:$E$252,"완료") -> 17 | C10: =COUNTIFS('작업 목록'!$G$2:$G$252,A10,'작업 목록'!$E$2:$E$252,"부분완료") -> 1 | D10: =COUNTIFS('작업 목록'!$G$2:$G$252,A10,'작업 목록'!$E$2:$E$252,"예정") -> 10 | E10: =SUM(B10:D10) -> 28 | F10: =IF(E10=0,0,(B10+C10*0.5)/E10) -> 0.625
A11: 10. 맵/레벨 | B11: =COUNTIFS('작업 목록'!$G$2:$G$252,A11,'작업 목록'!$E$2:$E$252,"완료") -> 7 | C11: =COUNTIFS('작업 목록'!$G$2:$G$252,A11,'작업 목록'!$E$2:$E$252,"부분완료") -> 4 | D11: =COUNTIFS('작업 목록'!$G$2:$G$252,A11,'작업 목록'!$E$2:$E$252,"예정") -> 2 | E11: =SUM(B11:D11) -> 13 | F11: =IF(E11=0,0,(B11+C11*0.5)/E11) -> 0.69230769
A12: 11. 이모트 & 소품 | B12: =COUNTIFS('작업 목록'!$G$2:$G$252,A12,'작업 목록'!$E$2:$E$252,"완료") -> 8 | C12: =COUNTIFS('작업 목록'!$G$2:$G$252,A12,'작업 목록'!$E$2:$E$252,"부분완료") -> 0 | D12: =COUNTIFS('작업 목록'!$G$2:$G$252,A12,'작업 목록'!$E$2:$E$252,"예정") -> 6 | E12: =SUM(B12:D12) -> 14 | F12: =IF(E12=0,0,(B12+C12*0.5)/E12) -> 0.57142857
A13: 12. 설정(옵션) 시스템 | B13: =COUNTIFS('작업 목록'!$G$2:$G$252,A13,'작업 목록'!$E$2:$E$252,"완료") -> 5 | C13: =COUNTIFS('작업 목록'!$G$2:$G$252,A13,'작업 목록'!$E$2:$E$252,"부분완료") -> 0 | D13: =COUNTIFS('작업 목록'!$G$2:$G$252,A13,'작업 목록'!$E$2:$E$252,"예정") -> 1 | E13: =SUM(B13:D13) -> 6 | F13: =IF(E13=0,0,(B13+C13*0.5)/E13) -> 0.83333333
... A15: 14. 출시 준비 | B15: =COUNTIFS('작업 목록'!$G$2:$G$252,A15,'작업 목록'!$E$2:$E$252,"완료") -> 1 | C15: =COUNTIFS('작업 목록'!$G$2:$G$252,A15,'작업 목록'!$E$2:$E$252,"부분완료") -> 0 | D15: =COUNTIFS('작업 목록'!$G$2:$G$252,A15,'작업 목록'!$E$2:$E$252,"예정") -> 6 | E15: =SUM(B15:D15) -> 7 | F15: =IF(E15=0,0,(B15+C15*0.5)/E15) -> 0.14285714
A16: 전체 합계 | B16: =SUM(B2:B15) -> 138 | C16: =SUM(C2:C15) -> 11 | D16: =SUM(D2:D15) -> 102 | E16: =SUM(E2:E15) -> 251 | F16: =IF(E16=0,0,(B16+C16*0.5)/E16) -> 0.57171315
